Workbook

Sheet Портрет
A1: МГУ им. М.В.Ломоносова
A2: Кафедра Финансы и кредит
A3: Дисциплина "Финансы"
A4: Проект по портфельному менеджменту
A5: Авторы | B5: Бекмурзаева Халима Э310
B6: Кикенова Алина Э310
B7: Угрюмова Полина Э310
B8: Капустина Алёна Э310
B9: Кузнецова Анастасия Э310
A12: ПЕРСОНАЛЬНАЯ ИНФОРМАЦИЯ
A13: Имя | B13: Руслан | C13: Бывший спортсмен, завершил карьеру
A14: Возраст | B14: 41 год
A15: Статус | B15: Безработный (по выбору) | C15: Хочет жить на инвестиции
A16: Дата оценки | B16: Декабрь 2025 | C16: Текущий момент: конец 2025 года
A18: СЕМЬЯ
A19: Супруга | B19: Жена
A20: Дети | B20: 3 детей школьного возраста
A22: ИМУЩЕСТВО И АКТИВЫ
A23: Квартира в Москве | B23: 42,500,000 ₽ | C23: Жилое помещение в центре
A24: 2 частных дома | B24: 165 700 000 *2=331 400 000₽ | C24: Дома в элитном подмосковном посёлке
A25: Дом в Дубае | B25: 630,000 USD (~48 млн ₽) | C25: Международная собственность
A26: ИТОГО НЕДВИЖИМОСТЬ | B26: =42500000+331400000+48000000 -> 421900000 | C26: Может быть ликвидирована при необходимости
A28: Деньги на депозите в России | B28: 900 000 000 ₽ | C28: ОСНОВНОЙ КАПИТАЛ ДЛЯ ИНВЕСТИЦИЙ
A29: Деньги в банке в Дубае | B29: 500 000$=38 000 000 | C29: ЕЩЕ КАПИТАЛ ДЛЯ ИНВЕСТИЦИЙ (1$=76руб)
A30: ОБЩЕЕ СОСТОЯНИЕ | B30: =900000000+38000000+B26 -> 1359900000 | C30: Недвижимость + Наличные
A32: ФИНАНСОВЫЕ ПАРАМЕТРЫ
A33: Годовые расходы | B33: 48,000,000 ₽ (4 млн/мес) | C33: Включает содержание семьи из 4 человек
A34: Резервный фонд | B34: 281,400,000 ₽ (30%) | C34: Резервный фонд
A35: Сумма для инвестиций | B35: 656,600,000 ₽ (70%) | C35: На брокерский счет для портфеля
A37: ПСИХОЛОГИЧЕСКИЙ ПРОФИЛЬ
A38: Отношение к риску | B38: КОНСЕРВАТИВНЫЙ | C38: Предпочитает надежность росту
A39: Отношение к работе | B39: Не хочет работать | C39: Хочет жить на пассивный доход
A40: Готовность к падению | B40: СРЕДНЯЯ (нужна подушка) | C40: Нужен резерв для психологического комфорта
A43: ФИНАНСОВЫЕ ЦЕЛИ
A44: Основная цель | B44: Финансовая независимость | C44: Портфель покрывает все расходы

Sheet Доходность облигации
A1: Название | B1: Тикер | C1: Премия | D1: Доля | E1: КС 2026 | F1: Доходность 2026 | G1: КС 2027 | H1: Доходность 2027 | I1: КС 2028 | J1: Доходность после
A2: ВЭБ.РФ ПБО-002Р-37 | B2: RU000A106LL5 | C2: 1.65 | D2: 0.075 | E2: 14 | F2: =C2+E2 -> 15.65 | G2: 8 | H2: =G2+C2 -> 9.65 | I2: 9 | J2: =I2+C2 -> 10.65
A3: ВЭБ.РФ ПБО-002Р-36 | B3: RU000A105YH8 | C3: 1.7 | D3: 0.075 | E3: 14 | F3: =C3+E3 -> 15.7 | G3: 8 | H3: =G3+C3 -> 9.7 | I3: 9 | J3: =I3+C3 -> 10.7
A4: ВЭБ.РФ ПБО-002Р-38 | B4: RU000A106WW9 | C4: 1.65 | D4: 0.075 | E4: 14 | F4: =C4+E4 -> 15.65 | G4: 8 | H4: =G4+C4 -> 9.65 | I4: 9 | J4: =I4+C4 -> 10.65
A5: ВЭБ.РФ ПБО-002Р-31 | B5: RU000A1042W6 | C5: 1.55 | D5: 0.075 | E5: 14 | F5: =C5+E5 -> 15.55 | G5: 8 | H5: =G5+C5 -> 9.55 | I5: 9 | J5: =I5+C5 -> 10.55
A6: ДОМ.РФ ПАО 002P-04 | B6: RU000A108FC2 | C6: 1.05 | D6: 0.075 | E6: 14 | F6: =C6+E6 -> 15.05 | G6: 8 | H6: =G6+C6 -> 9.05 | I6: 9 | J6: =I6+C6 -> 10.05
A7: ДОМ.РФ ПАО 002P-01 | B7: RU000A105MN1 | C7: 1.35 | D7: 0.075 | E7: 14 | F7: =C7+E7 -> 15.35 | G7: 8 | H7: =G7+C7 -> 9.35 | I7: 9 | J7: =I7+C7 -> 10.35
A8: Газпром нефть БО 003P-13R | B8: RU000A109B33 | C8: 1.3 | D8: 0.075 | E8: 14 | F8: =C8+E8 -> 15.3 | G8: 8 | H8: =G8+C8 -> 9.3 | I8: 9 | J8: =I8+C8 -> 10.3
A9: ФосАгро БО-02-01 | B9: RU000A10A4S7 | C9: 2 | D9: 0.075 | E9: 14 | F9: =C9+E9 -> 16 | G9: 8 | H9: =G9+C9 -> 10 | I9: 9 | J9: =I9+C9 -> 11
A10: РусГидро БО-002Р-01 | B10: RU000A10A349 | C10: 2 | D10: 0.075 | E10: 14 | F10: =C10+E10 -> 16 | G10: 8 | H10: =G10+C10 -> 10 | I10: 9 | J10: =I10+C10 -> 11
A11: Совкомбанк БО-П05 | B11: RU000A109VL8 | C11: 2 | D11: 0.075 | E11: 14 | F11: =C11+E11 -> 16 | G11: 8 | H11: =G11+C11 -> 10 | I11: 9 | J11: =I11+C11 -> 11
A12: Замещающие облигации | B12: RU000A106G80 | C12: 8.98 | D12: 0.25 | F12: =((1+0.0898)*(1+0.05)-1)*100 -> 14.429 | H12: =F12 -> 14.429 | J12: =H12 -> 14.429
A13: Общая доходность в п.п. | D13: =SUM(D2:D12) -> 1 | F13: =SUMPRODUCT(D2:D12,F2:F12) -> 15.326 | H13: =SUMPRODUCT(D2:D12,H2:H12) -> 10.826 | J13: =SUMPRODUCT(D2:D12,J2:J12) -> 11.576
A14: Общая доходность в % | F14: =F13/100 -> 0.15326 | H14: =H13/100 -> 0.10826 | J14: =J13/100 -> 0.11576
A16: Среднегодовой темп обесценивания рубля | B16: 0.05

Sheet Доходность акций
A1: Акции-60% от портфеля
E2: 0.6
A3: Компания | B3: Тикер | C3: Сектор | D3: Доля относительно акций | E3: Доля относительно портфеля | F3: β | G3: Ожидаемая доходность акций | H3: Средний доход по дивидендам за 5 лет в % (с 2020 по 2025 включая)
A4: ПАО "Сбербанк" | B4: SBER | C4: Финансовый сектор | D4: 0.1935 | E4: =D4*$E$2 -> 0.1161 | F4: 0.67647221 | G4: =$B$16+$B$17*F4 -> 0.23264722 | H4: 0.0937
A5: ПАО "Газпром" | B5: GAZP | C5: Энергетика | D5: 0.1398 | E5: =D5*$E$2 -> 0.08388 | F5: 0.73683891 | G5: =$B$16+$B$17*F5 -> 0.23868389 | H5: 0.10716667
A6: ПАО "Московская биржа" | B6: MOEX | C6: Финансовый сектор | D6: 0.1183 | E6: =D6*$E$2 -> 0.07098 | F6: 0.4636145 | G6: =$B$16+$B$17*F6 -> 0.21136145 | H6: 0.059666667
A7: ООО "Фосагро" | B7: PHOR | C7: Сырьевая промышленность | D7: 0.086 | E7: =D7*$E$2 -> 0.0516 | F7: 0.17452107 | G7: =$B$16+$B$17*F7 -> 0.18245211 | H7: 0.11073333
A8: ПАО "РусГидро" | B8: HYDR | C8: Электроэнергетика | D8: 0.0968 | E8: =D8*$E$2 -> 0.05808 | F8: 0.28266054 | G8: =$B$16+$B$17*F8 -> 0.19326605 | H8: 0.05862
A9: ПАО "Роснефть" | B9: ROSN | C9: Энергетика | D9: 0.0753 | E9: =D9*$E$2 -> 0.04518 | F9: 0.49537035 | G9: =$B$16+$B$17*F9 -> 0.21453703 | H9: 0.079666667
A10: ПАО "Лукойл" | B10: LKOH | C10: Энергетика | D10: 0.0968 | E10: =D10*$E$2 -> 0.05808 | F10: 0.2162762 | G10: =$B$16+$B$17*F10 -> 0.18662762 | H10: 0.13355
A11: ПАО "МТС" | B11: MTSS | C11: Телекоммуникации | D11: 0.0645 | E11: =D11*$E$2 -> 0.0387 | F11: 0.56888319 | G11: =$B$16+$B$17*F11 -> 0.22188832 | H11: 0.12433333
A12: ПАО "Татнефть" | B12: TATN | C12: Энергетика | D12: 0.0753 | E12: =D12*$E$2 -> 0.04518 | F12: 0.99924399 | G12: =$B$16+$B$17*F12 -> 0.2649244 | H12: 0.098633333
A13: ООО "Яндекс" | B13: YNDX | C13: Информационные технологии | D13: 0.0537 | E13: =D13*$E$2 -> 0.03222 | F13: 0.57139788 | G13: =$B$16+$B$17*F13 -> 0.22213979 | H13: 0.02855
D14: =SUM(D4:D13) -> 1 | E14: =SUM(E4:E13) -> 0.6 | H14: =AVERAGE(H4:H13) -> 0.089462
A16: Ключевая ставка % | B16: 0.165
A17: Премия за риск | B17: 0.1

Sheet Ребалансировка портфеля
D2: Брокерский счет | E2: Доходость акций | F2: Доходость облигаций | G2: Сумма направляемая на акции, руб | H2: Сумма направляемая на облигации, руб | I2: Рост акций, руб | J2: Купонный доход, руб | K2: Дивидендный доход, руб | L2: Стоимость портфеля на конец года, руб | M2: Резерв, руб | N2: Расходы, руб | O2: Вывод 4% | P2: Доп вывод | Q2: Кладёт на накоп счёт | R2: Накоп счет на конец года
C3: 2026 | D3: 656600000 | E3: 0.0749 | F3: 0.15326 | G3: =D3*0.6 -> 393960000 | H3: =D3*0.4 -> 262640000 | I3: =G3*(1+E3) -> 423467604 | J3: =H3*F3 -> 40252206 | K3: =G3*'Доходность акций'!$H$14*0.87 -> 30662671 | L3: =SUM(H3:K3) -> 7.5702248e+08 | M3: 281400000 | N3: 48000000 | O3: =0.04*L3 -> 30280899 | Q3: =O3-P3 -> 30280899 | R3: =Q3*1.16 -> 35125843
C4: 2027 | D4: =L3-(O3+P3) -> 7.2674158e+08 | E4: 0.3622 | F4: 0.10826 | G4: =D4*0.6 -> 4.3604495e+08 | H4: =D4*0.4 -> 2.9069663e+08 | I4: =G4*(1+E4) -> 5.9398043e+08 | J4: =H4*F4 -> 31470817 | K4: =G4*'Доходность акций'!$H$14*0.87 -> 33938224 | L4: =SUM(H4:K4) -> 9.500861e+08 | M4: =M3-N3 -> 233400000 | N4: =$N$3*(1+$C$25)^1 -> 51700800 | O4: =0.04*L4 -> 38003444 | Q4: =O4-P4 -> 38003444 | R4: =(R3+Q4)*1.16 -> 84829973 | S4: 1
C5: 2028 | D5: =L4-(O4+P4) -> 9.1208266e+08 | E5: 0.1686 | F5: 0.11576 | G5: =D5*0.6 -> 5.472496e+08 | H5: =D5*0.4 -> 3.6483306e+08 | I5: =G5*(1+E5) -> 6.3951588e+08 | J5: =H5*F5 -> 42233076 | K5: =G5*'Доходность акций'!$H$14*0.87 -> 42593498 | L5: =SUM(H5:K5) -> 1.0891755e+09 | M5: =M4-N4 -> 181699200 | N5: =$N$3*(1+$C$25)^2 -> 55686932 | O5: =0.04*L5 -> 43567021 | Q5: =O5-P5 -> 43567021 | R5: =(R4+Q5)*1.16 -> 1.4894051e+08 | S5: 2
C6: 2029 | D6: =L5-(O5+P5) -> 1.0456085e+09 | E6: 0.1686 | F6: =F5 -> 0.11576 | G6: =D6*0.6 -> 6.273651e+08 | H6: =D6*0.4 -> 4.182434e+08 | I6: =G6*(1+E6) -> 7.3313885e+08 | J6: =H6*F6 -> 48415856 | K6: =G6*'Доходность акций'!$H$14*0.87 -> 48829043 | L6: =SUM(H6:K6) -> 1.2486271e+09 | M6: =M5-N5 -> 1.2601227e+08 | N6: =$N$3*(1+$C$25)^3 -> 59980394 | O6: =0.04*L6 -> 49945086 | Q6: =O6-P6 -> 49945086 | R6: =(R5+Q6)*1.16 -> 2.3070729e+08 | S6: 3
C7: 2030 | D7: =L6-(O6+P6) -> 1.1986821e+09 | E7: -0.0461 | F7: =F5 -> 0.11576 | G7: =D7*0.6 -> 7.1920924e+08 | H7: =D7*0.4 -> 4.7947283e+08 | I7: =G7*(1+E7) -> 6.8605369e+08 | J7: =H7*F7 -> 55503774 | K7: =G7*'Доходность акций'!$H$14*0.87 -> 55977450 | L7: =SUM(H7:K7) -> 1.2770077e+09 | M7: =M6-N6 -> 66031874 | N7: =$N$3*(1+$C$25)^4 -> 64604882 | O7: =0.04*L7 -> 51080310 | Q7: =O7-P7 -> 51080310 | R7: =(R6+Q7)*1.16 -> 3.2687362e+08 | S7: 4
C8: 2031 | D8: =L7-(O7+P7) -> 1.2259274e+09 | E8: 0.5098 | F8: =F5 -> 0.11576 | G8: =D8*0.6 -> 7.3555646e+08 | H8: =D8*0.4 -> 4.9037097e+08 | I8: =G8*(1+E8) -> 1.1105431e+09 | J8: =H8*F8 -> 56765344 | K8: =G8*'Доходность акций'!$H$14*0.87 -> 57249786 | L8: =SUM(H8:K8) -> 1.7149292e+09 | M8: =M7-N7 -> 1426991.7 | N8: =$N$3*(1+$C$25)^5 -> 69585919 | O8: =0.04*L8 -> 68597170 | P8: 0 | Q8: =O8-P8 -> 68597170 | R8: =(R7+Q8)*1.16 -> 4.5874612e+08 | S8: 5
C9: 2032 | D9: =L8-(O8+P8) -> 1.6463321e+09 | E9: 0.0749 | F9: =F5 -> 0.11576 | G9: =D9*0.6 -> 9.8779924e+08 | H9: =D9*0.4 -> 6.5853283e+08 | I9: =G9*(1+E9) -> 1.0617854e+09 | J9: =H9*F9 -> 76231760 | K9: =G9*'Доходность акций'!$H$14*0.87 -> 76882332 | L9: =SUM(H9:K9) -> 1.8734323e+09 | M9: 0 | N9: =$N$3*(1+$C$25)^6 -> 74950993 | O9: =0.04*L9 -> 74937293 | P9: =N9-O9 -> 13700.081 | Q9: 0 | R9: =(R8+Q9)*1.16 -> 5.321455e+08 | S9: 6
C10: 2033 | D10: =L9-(O9+P9) -> 1.7984813e+09 | E10: 0.1638 | F10: =F5 -> 0.11576 | G10: =D10*0.6 -> 1.0790888e+09 | H10: =D10*0.4 -> 7.1939253e+08 | I10: =G10*(1+E10) -> 1.2558435e+09 | J10: =H10*F10 -> 83276880 | K10: =G10*'Доходность акций'!$H$14*0.87 -> 83987575 | L10: =SUM(H10:K10) -> 2.1425005e+09 | N10: =$N$3*(1+$C$25)^7 -> 80729715 | O10: =0.04*L10 -> 85700021 | P10: 0 | Q10: =O10-N10 -> 4970306.6 | R10: =(R9+Q10)*1.16 -> 6.2305433e+08 | S10: 7
C11: 2034 | D11: =L10-(O10+P10) -> 2.0568005e+09 | E11: 0.5098 | F11: =F5 -> 0.11576 | G11: =D11*0.6 -> 1.2340803e+09 | H11: =D11*0.4 -> 8.2272021e+08 | I11: =G11*(1+E11) -> 1.8632145e+09 | J11: =H11*F11 -> 95238091 | K11: =G11*'Доходность акций'!$H$14*0.87 -> 96050865 | L11: =SUM(H11:K11) -> 2.8772236e+09 | N11: =$N$3*(1+$C$25)^8 -> 86953976 | O11: =0.04*L11 -> 1.1508894e+08 | P11: 0 | Q11: =O11-N11 -> 28134969 | R11: =(R10+Q11)*1.16 -> 7.5537959e+08 | S11: 8
C12: 2035 | D12: =L11-(O11+P11) -> 2.7621347e+09 | E12: 0.3622 | F12: =F5 -> 0.11576 | G12: =D12*0.6 -> 1.6572808e+09 | H12: =D12*0.4 -> 1.1048539e+09 | I12: =G12*(1+E12) -> 2.2575479e+09 | J12: =H12*F12 -> 1.2789788e+08 | K12: =G12*'Доходность акций'!$H$14*0.87 -> 1.2898938e+08 | L12: =SUM(H12:K12) -> 3.619289e+09 | N12: =$N$3*(1+$C$25)^9 -> 93658127 | O12: =0.04*L12 -> 1.4477156e+08 | P12: 0 | Q12: =O12-N12 -> 51113434 | R12: =(R11+Q12)*1.16 -> 9.3553191e+08 | S12: 9
C13: 2036 | D13: =L12-(O12+P12) -> 3.4745175e+09 | E13: -0.0461 | F13: =F5 -> 0.11576 | G13: =D13*0.6 -> 2.0847105e+09 | H13: =D13*0.4 -> 1.389807e+09 | I13: =G13*(1+E13) -> 1.9886053e+09 | J13: =H13*F13 -> 1.6088406e+08 | K13: =G13*'Доходность акций'!$H$14*0.87 -> 1.6225706e+08 | L13: =SUM(H13:K13) -> 3.7015534e+09 | N13: =$N$3*(1+$C$25)^10 -> 1.0087917e+08 | O13: =0.04*L13 -> 1.4806214e+08 | P13: 0 | Q13: =O13-N13 -> 47182969 | R13: =(R12+Q13)*1.16 -> 1.1399493e+09 | S13: 10
C14: 2037 | D14: =L13-(O13+P13) -> 3.5534913e+09 | E14: 0.0749 | F14: =F5 -> 0.11576 | G14: =D14*0.6 -> 2.1320948e+09 | H14: =D14*0.4 -> 1.4213965e+09 | I14: =G14*(1+E14) -> 2.2917887e+09 | J14: =H14*F14 -> 1.6454086e+08 | K14: =G14*'Доходность акций'!$H$14*0.87 -> 1.6594507e+08 | L14: =SUM(H14:K14) -> 4.0436711e+09 | N14: =$N$3*(1+$C$25)^11 -> 1.0865695e+08 | O14: =0.04*L14 -> 1.6174685e+08 | P14: 0 | Q14: =O14-N14 -> 53089893 | R14: =(R13+Q14)*1.16 -> 1.3839254e+09 | S14: 11
C15: 2038 | D15: =L14-(O14+P14) -> 3.8819243e+09 | E15: 0.0749 | F15: =F5 -> 0.11576 | G15: =D15*0.6 -> 2.3291546e+09 | H15: =D15*0.4 -> 1.5527697e+09 | I15: =G15*(1+E15) -> 2.5036083e+09 | J15: =H15*F15 -> 1.7974862e+08 | K15: =G15*'Доходность акций'!$H$14*0.87 -> 1.8128262e+08 | L15: =SUM(H15:K15) -> 4.4174092e+09 | N15: =$N$3*(1+$C$25)^12 -> 1.170344e+08 | O15: =0.04*L15 -> 1.7669637e+08 | P15: 0 | Q15: =O15-N15 -> 59661964 | R15: =(R14+Q15)*1.16 -> 1.6745614e+09 | S15: 12
C16: 2039 | D16: =L15-(O15+P15) -> 4.2407128e+09 | E16: 0.0749 | F16: =F5 -> 0.11576 | G16: =D16*0.6 -> 2.5444277e+09 | H16: =D16*0.4 -> 1.6962851e+09 | I16: =G16*(1+E16) -> 2.7350053e+09 | J16: =H16*F16 -> 1.9636197e+08 | K16: =G16*'Доходность акций'!$H$14*0.87 -> 1.9803774e+08 | L16: =SUM(H16:K16) -> 4.8256902e+09 | N16: =$N$3*(1+$C$25)^13 -> 1.2605776e+08 | O16: =0.04*L16 -> 1.9302761e+08 | P16: 0 | Q16: =O16-N16 -> 66969851 | R16: =(R15+Q16)*1.16 -> 2.0201762e+09 | S16: 13
C17: 2040 | D17: =L16-(O16+P16) -> 4.6326626e+09 | E17: 0.0749 | F17: =F5 -> 0.11576 | G17: =D17*0.6 -> 2.7795976e+09 | H17: =D17*0.4 -> 1.853065e+09 | I17: =G17*(1+E17) -> 2.9877894e+09 | J17: =H17*F17 -> 2.1451081e+08 | K17: =G17*'Доходность акций'!$H$14*0.87 -> 2.1634147e+08 | L17: =SUM(H17:K17) -> 5.2717067e+09 | N17: =$N$3*(1+$C$25)^14 -> 1.3577681e+08 | O17: =0.04*L17 -> 2.1086827e+08 | P17: 0 | Q17: =O17-N17 -> 75091459 | R17: =(R16+Q17)*1.16 -> 2.4305105e+09 | S17: 14
C18: 2041 | D18: =L17-(O17+P17) -> 5.0608384e+09 | E18: 0.3622 | F18: =F5 -> 0.11576 | G18: =D18*0.6 -> 3.0365031e+09 | H18: =D18*0.4 -> 2.0243354e+09 | I18: =G18*(1+E18) -> 4.1363245e+09 | J18: =H18*F18 -> 2.3433706e+08 | K18: =G18*'Доходность акций'!$H$14*0.87 -> 2.3633692e+08 | L18: =SUM(H18:K18) -> 6.6313338e+09 | N18: =$N$3*(1+$C$25)^15 -> 1.462452e+08 | O18: =0.04*L18 -> 2.6525335e+08 | P18: 0 | Q18: =O18-N18 -> 1.1900815e+08 | R18: =(R17+Q18)*1.16 -> 2.9574416e+09 | S18: 15
C19: 2042 | D19: =L18-(O18+P18) -> 6.3660805e+09 | E19: 0.5098 | F19: =F5 -> 0.11576 | G19: =D19*0.6 -> 3.8196483e+09 | H19: =D19*0.4 -> 2.5464322e+09 | I19: =G19*(1+E19) -> 5.766905e+09 | J19: =H19*F19 -> 2.9477499e+08 | K19: =G19*'Доходность акций'!$H$14*0.87 -> 2.9729064e+08 | L19: =SUM(H19:K19) -> 8.9054028e+09 | N19: =$N$3*(1+$C$25)^16 -> 1.5752071e+08 | O19: =0.04*L19 -> 3.5621611e+08 | P19: 0 | Q19: =O19-N19 -> 1.9869541e+08 | R19: =(R18+Q19)*1.16 -> 3.6611189e+09 | S19: 16
C20: 2043 | D20: =L19-(O19+P19) -> 8.5491867e+09 | E20: -0.0461 | F20: =F5 -> 0.11576 | G20: =D20*0.6 -> 5.129512e+09 | H20: =D20*0.4 -> 3.4196747e+09 | I20: =G20*(1+E20) -> 4.8930415e+09 | J20: =H20*F20 -> 3.9586154e+08 | K20: =G20*'Доходность акций'!$H$14*0.87 -> 3.9923987e+08 | L20: =SUM(H20:K20) -> 9.1078176e+09 | N20: =$N$3*(1+$C$25)^17 -> 1.6966555e+08 | O20: =0.04*L20 -> 3.643127e+08 | P20: 0 | Q20: =O20-N20 -> 1.9464715e+08 | R20: =(R19+Q20)*1.16 -> 4.4726887e+09 | S20: 17
C21: 2044 | D21: =L20-(O20+P20) -> 8.7435049e+09 | E21: 0.1686 | F21: =F5 -> 0.11576 | G21: =D21*0.6 -> 5.246103e+09 | H21: =D21*0.4 -> 3.497402e+09 | I21: =G21*(1+E21) -> 6.1305959e+09 | J21: =H21*F21 -> 4.0485925e+08 | K21: =G21*'Доходность акций'!$H$14*0.87 -> 4.0831437e+08 | L21: =SUM(H21:K21) -> 1.0441171e+10 | N21: =$N$3*(1+$C$25)^18 -> 1.8274677e+08 | O21: =0.04*L21 -> 4.1764686e+08 | P21: 0 | Q21: =O21-N21 -> 2.3490009e+08 | R21: =(R20+Q21)*1.16 -> 5.460803e+09 | S21: 18
C22: 2045 | D22: =L21-(O21+P21) -> 1.0023525e+10 | E22: 0.3622 | F22: =F5 -> 0.11576 | G22: =D22*0.6 -> 6.0141148e+09 | H22: =D22*0.4 -> 4.0094099e+09 | I22: =G22*(1+E22) -> 8.1924272e+09 | J22: =H22*F22 -> 4.6412928e+08 | K22: =G22*'Доходность акций'!$H$14*0.87 -> 4.6809022e+08 | L22: =SUM(H22:K22) -> 1.3134057e+10 | N22: =$N$3*(1+$C$25)^19 -> 1.9683654e+08 | O22: =0.04*L22 -> 5.2536226e+08 | P22: 0 | Q22: =O22-N22 -> 3.2852572e+08 | R22: =(R21+Q22)*1.16 -> 6.7156213e+09 | S22: 19
C23: 2046 | D23: =L22-(O22+P22) -> 1.2608694e+10 | E23: 0.1686 | F23: =F5 -> 0.11576 | G23: =D23*0.6 -> 7.5652166e+09 | H23: =D23*0.4 -> 5.0434777e+09 | I23: =G23*(1+E23) -> 8.8407121e+09 | J23: =H23*F23 -> 5.8383298e+08 | K23: =G23*'Доходность акций'!$H$14*0.87 -> 5.8881548e+08 | L23: =SUM(I23,K23) -> 9.4295275e+09 | N23: =$N$3*(1+$C$25)^20 -> 2.1201264e+08 | O23: =0.04*L23 -> 3.771811e+08 | P23: 0 | Q23: =O23-N23 -> 1.6516846e+08 | R23: =(R22+Q23)*1.16 -> 7.9817161e+09 | S23: 20
B25: Инфляция | C25: 0.0771
B26: НДФЛ | C26: 0.13

Sheet Сценарии и риски
B3: Основные параметры | C3: Доход акций
C4: Доход облигаций
C5: Инфляция
C6: Портфель
C7: Финальный портфель
B10: Базовый сценарий (см. лист "Ребалансировка портфеля") | E10: Комментарий
B11: Чем вызван сценарий | C11: Причина | D11: Стабильное развитие российского рынка
C12: Условия | D12: Отсутствие масштабных кризисов
C13: Предпосылка | D13: Сохранение доходности активов
B14: Что меняется и на сколько | C14: Доход акций | D14: НЕ МЕНЯЕТСЯ | E14: Базовый уровень
C15: Доход облигаций | D15: НЕ МЕНЯЕТСЯ | E15: Базовый уровень
C16: Инфляция | D16: НЕ МЕНЯЕТСЯ | E16: Нормальная инфляция
C17: Расходы | D17: +7.71% ежегодно | E17: Индексируются на инфляцию
B18: Риски | C18: Риск 1 | D18: Непредвиденное увеличение расходов на образование детей | E18: Потребность в дополнительных школах, олимпиадной подготовке, спорте на профессиональном уровне
C19: Риск 2 | D19: Консервативная психология инвестора при рыночной волатильности (переход с 60% акций на 80% облигаций) | E19: Риск эмоциональных решений
C20: Риск 3 | D20: Валютный риск облигационного портфеля (девальвация рубля 5-10% в год съедает номинальную доходность облигаций) | E20: РФ может быть более инфляционна, нужна частичная защита в валюте
B21: Ключевые показатели | C21: Финальный портфель | D21: 9,4 млрд ₽
B23: Оптимистичный сценарий | E23: Комментарий
B24: Чем вызван сценарий | C24: Причина | D24: Более волатильный рынок с циклами
C25: Условия | D25: Благоприятные условия чередуются с падениями
C26: Предпосылка | D26: Периодические просадки акций на -10%
B27: Что меняется и на сколько | C27: Доход акций | D27: +3 п.п.
C28: Доход облигаций | D28: +2 п.п. | E28: Выше чем в базовом
C29: Инфляция | D29: -1 п.п. | E29: Нижняя инфляция
C30: Расходы | D30: +6.71% ежегодно | E30: Растут медленнее
B31: Риски | C31: Риск 1 | D31: Расширение обязательств семьи из-за возросшего благосостояния | E31: Филантропия, инвестиции в стартапы, расширение недвижимости
C32: Риск 2 | D32: Перекредитование или гарантирование обязательств третьих лиц (инвестиция в стартап 100 млн ₽) | E32: Высокие риски новых финансовых обязательств при эйфории, ожидаемое значение -40 млм за операцию
C33: Риск 3 | D33: Недостаточная диверсификация международных активов | E33: РФ может быть более инфляционна
B34: Ключевые показатели | C34: Финальный портфель | D34: 10,2 млрд ₽
B36: Пессимистичный сценарий | E36: Комментарий
B37: Чем вызван сценарий | C37: Причина 1 | D37: Экономический кризис со стагфляцией
C38: Причина 2 | D38: Санкции и геополитическая напряженность
C39: Причина 3 | D39: Коллапс финансовых рынков
C40: Причина 4 | D40: Высокая инфляция + низкие доходы активов
B41: Что меняется и на сколько | C41: Доход акций | D41: -6 п.п. | E41: Критическое падение
C42: Доход облигаций | D42: -4 п.п. | E42: Облигации теряют ценность
C43: Инфляция | D43: +3 п.п. | E43: Стагфляция
C44: Расходы | D44: +9.71% ежегодно | E44: Растут быстро доходов
B45: Риски | C45: Риск 1 | D45: Возрастание обязательных платежей (инфляция 9.71% vs низкие доходы портфеля) | E45: Стагфляция: расходы растут, резерв исчезает к 2032-2033, "ножницы" сжимают портфель
C46: Риск 2 | D46: Сокращение финансирования спортшколы | E46: Школа теряет репутацию и конкурентоспособность, программы сокращаются, потеря репутационного капитала
...

Sheet Оптимистичный сценарий
D2: Брокерский счет | E2: Доходость акций | F2: Доходость облигаций | G2: Сумма направляемая на акции, руб | H2: Сумма направляемая на облигации, руб | I2: Рост акций, руб | J2: Купонный доход, руб | K2: Дивидендный доход, руб | L2: Стоимость портфеля на конец года, руб | M2: Резерв, руб | N2: Расходы, руб | O2: Вывод 4% | P2: Доп вывод | Q2: Кладёт на накоп счёт | R2: Накоп счет на конец года
C3: 2026 | D3: 656600000 | E3: 0.077147 | F3: 0.157858 | G3: =D3*0.6 -> 393960000 | H3: =D3*0.4 -> 262640000 | I3: =G3*(1+E3) -> 4.2435283e+08 | J3: =H3*F3 -> 41459825 | K3: =G3*'[1]Доходность акций'!$H$14*0.87 -> 30662671 | L3: =SUM(H3:K3) -> 7.5911533e+08 | M3: 281400000 | N3: 48000000 | O3: =0.04*L3 -> 30364613 | Q3: =O3-P3 -> 30364613 | R3: =Q3*1.16 -> 35222951
C4: 2027 | D4: =L3-(O3+P3) -> 7.2875072e+08 | E4: 0.373066 | F4: 0.111508 | G4: =D4*0.6 -> 4.3725043e+08 | H4: =D4*0.4 -> 2.9150029e+08 | I4: =G4*(1+E4) -> 6.003737e+08 | J4: =H4*F4 -> 32504614 | K4: =G4*'[1]Доходность акций'!$H$14*0.87 -> 34032049 | L4: =SUM(H4:K4) -> 9.5841065e+08 | M4: =M3-N3 -> 233400000 | N4: =$N$3*(1+$C$25)^1 -> 51220800 | O4: =0.04*L4 -> 38336426 | Q4: =O4-P4 -> 38336426 | R4: =(R3+Q4)*1.16 -> 85328877 | S4: 1
C5: 2028 | D5: =L4-O4 -> 9.2007422e+08 | E5: 0.173658 | F5: 0.119233 | G5: =D5*0.6 -> 5.5204453e+08 | H5: =D5*0.4 -> 3.6802969e+08 | I5: =G5*(1+E5) -> 6.4791148e+08 | J5: =H5*F5 -> 43881284 | K5: =G5*'[1]Доходность акций'!$H$14*0.87 -> 42966697 | L5: =SUM(H5:K5) -> 1.1027892e+09 | M5: =M4-N4 -> 182179200 | N5: =$N$3*(1+$C$25)^2 -> 54657716 | O5: =0.04*L5 -> 44111566 | Q5: =O5-P5 -> 44111566 | R5: =(R4+Q5)*1.16 -> 1.5015091e+08 | S5: 2
C6: 2029 | D6: =L5-O5 -> 1.0586776e+09 | E6: 0.173658 | F6: =F5 -> 0.119233 | G6: =D6*0.6 -> 6.3520655e+08 | H6: =D6*0.4 -> 4.2347103e+08 | I6: =G6*(1+E6) -> 7.4551525e+08 | J6: =H6*F6 -> 50491722 | K6: =G6*'[1]Доходность акций'!$H$14*0.87 -> 49439358 | L6: =SUM(H6:K6) -> 1.2689174e+09 | M6: =M5-N5 -> 1.2752148e+08 | N6: =$N$3*(1+$C$25)^3 -> 58325248 | O6: =0.04*L6 -> 50756695 | Q6: =O6-P6 -> 50756695 | R6: =(R5+Q6)*1.16 -> 2.3305283e+08 | S6: 3
C7: 2030 | D7: =L6-O6 -> 1.2181607e+09 | E7: -0.047483 | F7: =F5 -> 0.119233 | G7: =D7*0.6 -> 7.308964e+08 | H7: =D7*0.4 -> 4.8726427e+08 | I7: =G7*(1+E7) -> 6.9619125e+08 | J7: =H7*F7 -> 58097980 | K7: =G7*'[1]Доходность акций'!$H$14*0.87 -> 56887085 | L7: =SUM(H7:K7) -> 1.2984406e+09 | M7: =M6-N6 -> 69196236 | N7: =$N$3*(1+$C$25)^4 -> 62238873 | O7: =0.04*L7 -> 51937623 | Q7: =O7-P7 -> 51937623 | R7: =(R6+Q7)*1.16 -> 3.3058892e+08 | S7: 4
C8: 2031 | D8: =L7-O7 -> 1.246503e+09 | E8: 0.525094 | F8: =F5 -> 0.119233 | G8: =D8*0.6 -> 7.4790177e+08 | H8: =D8*0.4 -> 4.9860118e+08 | I8: =G8*(1+E8) -> 1.1406205e+09 | J8: =H8*F8 -> 59449715 | K8: =G8*'[1]Доходность акций'!$H$14*0.87 -> 58210646 | L8: =SUM(H8:K8) -> 1.7568821e+09 | M8: =M7-N7 -> 6957363.3 | N8: =$N$3*(1+$C$25)^5 -> 66415101 | O8: =0.04*L8 -> 70275282 | Q8: =O8-N8 -> 3860181.2 | R8: =(R7+Q8)*1.16 -> 3.8796096e+08 | S8: 5
C9: 2032 | D9: =L8-O8 -> 1.6866068e+09 | E9: 0.077147 | F9: =F5 -> 0.119233 | G9: =D9*0.6 -> 1.0119641e+09 | H9: =D9*0.4 -> 6.7464271e+08 | I9: =G9*(1+E9) -> 1.0900341e+09 | J9: =H9*F9 -> 80439674 | K9: =G9*'[1]Доходность акций'!$H$14*0.87 -> 78763126 | L9: =SUM(H9:K9) -> 1.9238796e+09 | M9: 0 | N9: =$N$3*(1+$C$25)^6 -> 70871554 | O9: =0.04*L9 -> 76955183 | Q9: =O9-N9 -> 6083628.3 | R9: =(R8+Q9)*1.16 -> 4.5709172e+08 | S9: 6
C10: 2033 | D10: =L9-O9 -> 1.8469244e+09 | E10: 0.168714 | F10: =F5 -> 0.119233 | G10: =D10*0.6 -> 1.1081546e+09 | H10: =D10*0.4 -> 7.3876975e+08 | I10: =G10*(1+E10) -> 1.2951158e+09 | J10: =H10*F10 -> 88085734 | K10: =G10*'[1]Доходность акций'!$H$14*0.87 -> 86249825 | L10: =SUM(H10:K10) -> 2.2082211e+09 | N10: =$N$3*(1+$C$25)^7 -> 75627035 | O10: =0.04*L10 -> 88328846 | Q10: =O10-N10 -> 12701810 | R10: =(R9+Q10)*1.16 -> 5.449605e+08 | S10: 7
C11: 2034 | D11: =L10-O10 -> 2.1198923e+09 | E11: 0.525094 | F11: =F5 -> 0.119233 | G11: =D11*0.6 -> 1.2719354e+09 | H11: =D11*0.4 -> 8.4795692e+08 | I11: =G11*(1+E11) -> 1.939821e+09 | J11: =H11*F11 -> 1.0110445e+08 | K11: =G11*'[1]Доходность акций'!$H$14*0.87 -> 98997198 | L11: =SUM(H11:K11) -> 2.9878796e+09 | N11: =$N$3*(1+$C$25)^8 -> 80701610 | O11: =0.04*L11 -> 1.1951518e+08 | Q11: =O11-N11 -> 38813573 | R11: =(R10+Q11)*1.16 -> 6.7717792e+08 | S11: 8
C12: 2035 | D12: =L11-O11 -> 2.8683644e+09 | E12: 0.373066 | F12: =F5 -> 0.119233 | G12: =D12*0.6 -> 1.7210186e+09 | H12: =D12*0.4 -> 1.1473458e+09 | I12: =G12*(1+E12) -> 2.3630722e+09 | J12: =H12*F12 -> 1.3680148e+08 | K12: =G12*'[1]Доходность акций'!$H$14*0.87 -> 1.3395022e+08 | L12: =SUM(H12:K12) -> 3.7811696e+09 | N12: =$N$3*(1+$C$25)^9 -> 86116688 | O12: =0.04*L12 -> 1.5124678e+08 | Q12: =O12-N12 -> 65130097 | R12: =(R11+Q12)*1.16 -> 8.610773e+08 | S12: 9
C13: 2036 | D13: =L12-O12 -> 3.6299228e+09 | E13: -0.047483 | F13: =F5 -> 0.119233 | G13: =D13*0.6 -> 2.1779537e+09 | H13: =D13*0.4 -> 1.4519691e+09 | I13: =G13*(1+E13) -> 2.0745379e+09 | J13: =H13*F13 -> 1.7312264e+08 | K13: =G13*'[1]Доходность акций'!$H$14*0.87 -> 1.6951436e+08 | L13: =SUM(H13:K13) -> 3.8691441e+09 | N13: =$N$3*(1+$C$25)^10 -> 91895117 | O13: =0.04*L13 -> 1.5476576e+08 | Q13: =O13-N13 -> 62870645 | R13: =(R12+Q13)*1.16 -> 1.0717796e+09 | S13: 10
C14: 2037 | D14: =L13-O13 -> 3.7143783e+09 | E14: 0.077147 | F14: =F5 -> 0.119233 | G14: =D14*0.6 -> 2.228627e+09 | H14: =D14*0.4 -> 1.4857513e+09 | I14: =G14*(1+E14) -> 2.4005589e+09 | J14: =H14*F14 -> 1.7715059e+08 | K14: =G14*'[1]Доходность акций'!$H$14*0.87 -> 1.7345836e+08 | L14: =SUM(H14:K14) -> 4.2369191e+09 | N14: =$N$3*(1+$C$25)^11 -> 98061280 | O14: =0.04*L14 -> 1.6947677e+08 | Q14: =O14-N14 -> 71415486 | R14: =(R13+Q14)*1.16 -> 1.3261063e+09 | S14: 11
C15: 2038 | D15: =L14-O14 -> 4.0674424e+09 | E15: 0.077147 | F15: =F5 -> 0.119233 | G15: =D15*0.6 -> 2.4404654e+09 | H15: =D15*0.4 -> 1.6269769e+09 | I15: =G15*(1+E15) -> 2.62874e+09 | J15: =H15*F15 -> 1.9398934e+08 | K15: =G15*'[1]Доходность акций'!$H$14*0.87 -> 1.8994616e+08 | L15: =SUM(H15:K15) -> 4.6396525e+09 | N15: =$N$3*(1+$C$25)^12 -> 1.0464119e+08 | O15: =0.04*L15 -> 1.855861e+08 | Q15: =O15-N15 -> 80944907 | R15: =(R14+Q15)*1.16 -> 1.6321794e+09 | S15: 12
C16: 2039 | D16: =L15-O15 -> 4.4540664e+09 | E16: 0.077147 | F16: =F5 -> 0.119233 | G16: =D16*0.6 -> 2.6724398e+09 | H16: =D16*0.4 -> 1.7816265e+09 | I16: =G16*(1+E16) -> 2.8786105e+09 | J16: =H16*F16 -> 2.1242868e+08 | K16: =G16*'[1]Доходность акций'!$H$14*0.87 -> 2.0800118e+08 | L16: =SUM(H16:K16) -> 5.0806669e+09 | N16: =$N$3*(1+$C$25)^13 -> 1.1166262e+08 | O16: =0.04*L16 -> 2.0322668e+08 | Q16: =O16-N16 -> 91564061 | R16: =(R15+Q16)*1.16 -> 1.9995424e+09 | S16: 13
C17: 2040 | D17: =L16-O16 -> 4.8774402e+09 | E17: 0.077147 | F17: =F5 -> 0.119233 | G17: =D17*0.6 -> 2.9264641e+09 | H17: =D17*0.4 -> 1.9509761e+09 | I17: =G17*(1+E17) -> 3.1522321e+09 | J17: =H17*F17 -> 2.3262073e+08 | K17: =G17*'[1]Доходность акций'!$H$14*0.87 -> 2.2777238e+08 | L17: =SUM(H17:K17) -> 5.5636013e+09 | N17: =$N$3*(1+$C$25)^14 -> 1.1915518e+08 | O17: =0.04*L17 -> 2.2254405e+08 | Q17: =O17-N17 -> 1.0338887e+08 | R17: =(R16+Q17)*1.16 -> 2.4394003e+09 | S17: 14
C18: 2041 | D18: =L17-O17 -> 5.3410572e+09 | E18: 0.373066 | F18: =F5 -> 0.119233 | G18: =D18*0.6 -> 3.2046343e+09 | H18: =D18*0.4 -> 2.1364229e+09 | I18: =G18*(1+E18) -> 4.4001745e+09 | J18: =H18*F18 -> 2.5473211e+08 | K18: =G18*'[1]Доходность акций'!$H$14*0.87 -> 2.4942291e+08 | L18: =SUM(H18:K18) -> 7.0407524e+09 | N18: =$N$3*(1+$C$25)^15 -> 1.2715049e+08 | O18: =0.04*L18 -> 2.8163009e+08 | Q18: =O18-N18 -> 1.5447961e+08 | R18: =(R17+Q18)*1.16 -> 3.0089007e+09 | S18: 15
C19: 2042 | D19: =L18-O18 -> 6.7591223e+09 | E19: 0.525094 | F19: =F5 -> 0.119233 | G19: =D19*0.6 -> 4.0554734e+09 | H19: =D19*0.4 -> 2.7036489e+09 | I19: =G19*(1+E19) -> 6.1849781e+09 | J19: =H19*F19 -> 3.2236417e+08 | K19: =G19*'[1]Доходность акций'!$H$14*0.87 -> 3.1564536e+08 | L19: =SUM(H19:K19) -> 9.5266365e+09 | N19: =$N$3*(1+$C$25)^16 -> 1.3568229e+08 | O19: =0.04*L19 -> 3.8106546e+08 | Q19: =O19-N19 -> 2.4538317e+08 | R19: =(R18+Q19)*1.16 -> 3.7749693e+09 | S19: 16
C20: 2043 | D20: =L19-O19 -> 9.1455711e+09 | E20: -0.0461 | F20: =F5 -> 0.119233 | G20: =D20*0.6 -> 5.4873426e+09 | H20: =D20*0.4 -> 3.6582284e+09 | I20: =G20*(1+E20) -> 5.2343762e+09 | J20: =H20*F20 -> 4.3618155e+08 | K20: =G20*'[1]Доходность акций'!$H$14*0.87 -> 4.2709052e+08 | L20: =SUM(H20:K20) -> 9.7558767e+09 | N20: =$N$3*(1+$C$25)^17 -> 1.4478657e+08 | O20: =0.04*L20 -> 3.9023507e+08 | Q20: =O20-N20 -> 2.454485e+08 | R20: =(R19+Q20)*1.16 -> 4.6636847e+09 | S20: 17
C21: 2044 | D21: =L20-O20 -> 9.3656416e+09 | E21: 0.173658 | F21: =F5 -> 0.119233 | G21: =D21*0.6 -> 5.619385e+09 | H21: =D21*0.4 -> 3.7462566e+09 | I21: =G21*(1+E21) -> 6.5952361e+09 | J21: =H21*F21 -> 4.4667742e+08 | K21: =G21*'[1]Доходность акций'!$H$14*0.87 -> 4.3736763e+08 | L21: =SUM(H21:K21) -> 1.1225538e+10 | N21: =$N$3*(1+$C$25)^18 -> 1.5450175e+08 | O21: =0.04*L21 -> 4.4902151e+08 | Q21: =O21-N21 -> 2.9451976e+08 | R21: =(R20+Q21)*1.16 -> 5.7515171e+09 | S21: 18
C22: 2045 | D22: =L21-O21 -> 1.0776516e+10 | E22: 0.373066 | F22: =F5 -> 0.119233 | G22: =D22*0.6 -> 6.4659098e+09 | H22: =D22*0.4 -> 4.3106065e+09 | I22: =G22*(1+E22) -> 8.8781209e+09 | J22: =H22*F22 -> 5.1396655e+08 | K22: =G22*'[1]Доходность акций'!$H$14*0.87 -> 5.032543e+08 | L22: =SUM(H22:K22) -> 1.4205948e+10 | N22: =$N$3*(1+$C$25)^19 -> 1.6486881e+08 | O22: =0.04*L22 -> 5.6823793e+08 | Q22: =O22-N22 -> 4.0336911e+08 | R22: =(R21+Q22)*1.16 -> 7.1396681e+09 | S22: 19
C23: 2046 | D23: =L22-O22 -> 1.363771e+10 | E23: 0.173658 | F23: =F5 -> 0.119233 | G23: =D23*0.6 -> 8.1826262e+09 | H23: =D23*0.4 -> 5.4550841e+09 | I23: =G23*(1+E23) -> 9.6036047e+09 | J23: =H23*F23 -> 6.5042604e+08 | K23: =G23*'[1]Доходность акций'!$H$14*0.87 -> 6.3686967e+08 | L23: =SUM(I23,K23) -> 1.0240474e+10 | N23: =$N$3*(1+$C$25)^20 -> 1.7593151e+08 | O23: =0.04*L23 -> 4.0961897e+08 | Q23: =O23-N23 -> 2.3368746e+08 | R23: =(R22+Q23)*1.16 -> 8.5530924e+09 | S23: 20
B25: Инфляция | C25: 0.0671
B26: НДФЛ | C26: 0.13

Sheet Пессимистиный сценарий
D2: Брокерский счет | E2: Доходость акций | F2: Доходость облигаций | G2: Сумма направляемая на акции, руб | H2: Сумма направляемая на облигации, руб | I2: Рост акций, руб | J2: Купонный доход, руб | K2: Дивидендный доход, руб | L2: Стоимость портфеля на конец года, руб | M2: Резерв, руб | N2: Расходы, руб | O2: Вывод 4% | P2: Доп вывод | Q2: Кладёт на накоп счёт | R2: Накоп счет на конец года
C3: 2026 | D3: 656600000 | E3: 0.070406 | F3: 0.1471296 | G3: =D3*0.6 -> 393960000 | H3: =D3*0.4 -> 262640000 | I3: =G3*(1+E3) -> 4.2169715e+08 | J3: =H3*F3 -> 38642118 | K3: =G3*'[1]Доходность акций'!$H$14*0.87 -> 30662671 | L3: =SUM(H3:K3) -> 7.5364194e+08 | M3: 281400000 | N3: 48000000 | O3: =0.04*L3 -> 30145677 | Q3: =O3-P3 -> 30145677 | R3: =Q3*1.16 -> 34968986
C4: 2027 | D4: =L3-(O3+P3) -> 7.2349626e+08 | E4: 0.340468 | F4: 0.1039296 | G4: =D4*0.6 -> 4.3409776e+08 | H4: =D4*0.4 -> 2.893985e+08 | I4: =G4*(1+E4) -> 5.8189415e+08 | J4: =H4*F4 -> 30077071 | K4: =G4*'[1]Доходность акций'!$H$14*0.87 -> 33786670 | L4: =SUM(H4:K4) -> 9.351564e+08 | M4: =M3-N3 -> 233400000 | N4: =$N$3*(1+$C$25)^1 -> 52660800 | O4: =0.04*L4 -> 37406256 | Q4: =O4-P4 -> 37406256 | R4: =(R3+Q4)*1.16 -> 83955280 | S4: 1
C5: 2028 | D5: =L4-(O4+P4) -> 8.9775014e+08 | E5: 0.158484 | F5: 0.1111488 | G5: =D5*0.6 -> 5.3865008e+08 | H5: =D5*0.4 -> 3.5910006e+08 | I5: =G5*(1+E5) -> 6.240175e+08 | J5: =H5*F5 -> 39913540 | K5: =G5*'[1]Доходность акций'!$H$14*0.87 -> 41924181 | L5: =SUM(H5:K5) -> 1.0649553e+09 | M5: =M4-N4 -> 180739200 | N5: =$N$3*(1+$C$25)^2 -> 57774164 | O5: =0.04*L5 -> 42598211 | Q5: =O5-P5 -> 42598211 | R5: =(R4+Q5)*1.16 -> 1.4680205e+08 | S5: 2
C6: 2029 | D6: =L5-(O5+P5) -> 1.0223571e+09 | E6: 0.168484 | F6: =F5 -> 0.1111488 | G6: =D6*0.6 -> 6.1341424e+08 | H6: =D6*0.4 -> 4.0894283e+08 | I6: =G6*(1+E6) -> 7.1676473e+08 | J6: =H6*F6 -> 45453505 | K6: =G6*'[1]Доходность акций'!$H$14*0.87 -> 47743220 | L6: =SUM(H6:K6) -> 1.2189043e+09 | M6: =M5-N5 -> 1.2296504e+08 | N6: =$N$3*(1+$C$25)^3 -> 63384035 | O6: =0.04*L6 -> 48756171 | Q6: =O6-P6 -> 48756171 | R6: =(R5+Q6)*1.16 -> 2.2684754e+08 | S6: 3
C7: 2030 | D7: =L6-(O6+P6) -> 1.1701481e+09 | E7: -0.043334 | F7: =F5 -> 0.1111488 | G7: =D7*0.6 -> 7.0208887e+08 | H7: =D7*0.4 -> 4.6805924e+08 | I7: =G7*(1+E7) -> 6.7166455e+08 | J7: =H7*F7 -> 52024223 | K7: =G7*'[1]Доходность акций'!$H$14*0.87 -> 54644938 | L7: =SUM(H7:K7) -> 1.246393e+09 | M7: =M6-N6 -> 59581001 | N7: =$N$3*(1+$C$25)^4 -> 69538625 | O7: =0.04*L7 -> 49855718 | Q7: =O7-(N7-M7) -> 39898095 | R7: =(R6+Q7)*1.16 -> 3.0942493e+08 | S7: 4
C8: 2031 | D8: =L7-(O7+P7) -> 1.1965372e+09 | E8: 0.479212 | F8: =F5 -> 0.1111488 | G8: =D8*0.6 -> 7.1792234e+08 | H8: =D8*0.4 -> 4.7861489e+08 | I8: =G8*(1+E8) -> 1.0619593e+09 | J8: =H8*F8 -> 53197471 | K8: =G8*'[1]Доходность акций'!$H$14*0.87 -> 55877288 | L8: =SUM(H8:K8) -> 1.649649e+09 | M8: 0 | N8: =$N$3*(1+$C$25)^5 -> 76290825 | O8: =0.04*L8 -> 65985960 | P8: =N8-O8 -> 10304866 | Q8: 0 | R8: =(R7+Q8)*1.16 -> 3.5893292e+08 | S8: 5
C9: 2032 | D9: =L8-(O8+P8) -> 1.5733582e+09 | E9: 0.070406 | F9: =F5 -> 0.1111488 | G9: =D9*0.6 -> 9.440149e+08 | H9: =D9*0.4 -> 6.2934327e+08 | I9: =G9*(1+E9) -> 1.0104792e+09 | J9: =H9*F9 -> 69950749 | K9: =G9*'[1]Доходность акций'!$H$14*0.87 -> 73474511 | L9: =SUM(H9:K9) -> 1.7832477e+09 | N9: =$N$3*(1+$C$25)^6 -> 83698664 | O9: =0.04*L9 -> 71329910 | P9: =N9-O9 -> 12368755 | Q9: 0 | R9: =(R8+Q9)*1.16 -> 4.1636219e+08 | S9: 6
C10: 2033 | D10: =L9-(O9+P9) -> 1.6995491e+09 | E10: 0.153972 | F10: =F5 -> 0.1111488 | G10: =D10*0.6 -> 1.0197294e+09 | H10: =D10*0.4 -> 6.7981963e+08 | I10: =G10*(1+E10) -> 1.1767392e+09 | J10: =H10*F10 -> 75561136 | K10: =G10*'[1]Доходность акций'!$H$14*0.87 -> 79367521 | L10: =SUM(H10:K10) -> 2.0114875e+09 | N10: =$N$3*(1+$C$25)^7 -> 91825805 | O10: =0.04*L10 -> 80459501 | P10: =N10-O10 -> 11366304 | Q10: 0 | R10: =(R9+Q10)*1.16 -> 4.8298014e+08 | S10: 7
C11: 2034 | D11: =L10-(O10+P10) -> 1.9196617e+09 | E11: 0.479212 | F11: =F5 -> 0.1111488 | G11: =D11*0.6 -> 1.151797e+09 | H11: =D11*0.4 -> 7.6786468e+08 | I11: =G11*(1+E11) -> 1.703752e+09 | J11: =H11*F11 -> 85347238 | K11: =G11*'[1]Доходность акций'!$H$14*0.87 -> 89646597 | L11: =SUM(H11:K11) -> 2.6466105e+09 | N11: =$N$3*(1+$C$25)^8 -> 1.0074209e+08 | O11: =0.04*L11 -> 1.0586442e+08 | P11: 0 | Q11: =O11-N11 -> 5122329.8 | R11: =(R10+Q11)*1.16 -> 5.6619886e+08 | S11: 8
C12: 2035 | D12: =L11-(O11+P11) -> 2.5407461e+09 | E12: 0.340468 | F12: =F5 -> 0.1111488 | G12: =D12*0.6 -> 1.5244477e+09 | H12: =D12*0.4 -> 1.0162984e+09 | I12: =G12*(1+E12) -> 2.0434733e+09 | J12: =H12*F12 -> 1.1296035e+08 | K12: =G12*'[1]Доходность акций'!$H$14*0.87 -> 1.1865072e+08 | L12: =SUM(H12:K12) -> 3.2913828e+09 | N12: =$N$3*(1+$C$25)^9 -> 1.1052415e+08 | O12: =0.04*L12 -> 1.3165531e+08 | P12: 0 | Q12: =O12-N12 -> 21131165 | R12: =(R11+Q12)*1.16 -> 6.8130283e+08 | S12: 9
C13: 2036 | D13: =L12-(O12+P12) -> 3.1597275e+09 | E13: -0.043334 | F13: =F5 -> 0.1111488 | G13: =D13*0.6 -> 1.8958365e+09 | H13: =D13*0.4 -> 1.263891e+09 | I13: =G13*(1+E13) -> 1.8136823e+09 | J13: =H13*F13 -> 1.4047997e+08 | K13: =G13*'[1]Доходность акций'!$H$14*0.87 -> 1.4755663e+08 | L13: =SUM(H13:K13) -> 3.3656099e+09 | N13: =$N$3*(1+$C$25)^10 -> 1.2125604e+08 | O13: =0.04*L13 -> 1.346244e+08 | P13: 0 | Q13: =O13-N13 -> 13368354 | R13: =(R12+Q13)*1.16 -> 8.0581858e+08 | S13: 10
C14: 2037 | D14: =L13-(O13+P13) -> 3.2309855e+09 | E14: 0.070406 | F14: =F5 -> 0.1111488 | G14: =D14*0.6 -> 1.9385913e+09 | H14: =D14*0.4 -> 1.2923942e+09 | I14: =G14*(1+E14) -> 2.0750798e+09 | J14: =H14*F14 -> 1.4364806e+08 | K14: =G14*'[1]Доходность акций'!$H$14*0.87 -> 1.5088432e+08 | L14: =SUM(H14:K14) -> 3.6620064e+09 | N14: =$N$3*(1+$C$25)^11 -> 1.3303e+08 | O14: =0.04*L14 -> 1.4648025e+08 | P14: 0 | Q14: =O14-N14 -> 13450251 | R14: =(R13+Q14)*1.16 -> 9.5035184e+08 | S14: 11
C15: 2038 | D15: =L14-(O14+P14) -> 3.5155261e+09 | E15: 0.070406 | F15: =F5 -> 0.1111488 | G15: =D15*0.6 -> 2.1093157e+09 | H15: =D15*0.4 -> 1.4062104e+09 | I15: =G15*(1+E15) -> 2.2578241e+09 | J15: =H15*F15 -> 1.562986e+08 | K15: =G15*'[1]Доходность акций'!$H$14*0.87 -> 1.6417213e+08 | L15: =SUM(H15:K15) -> 3.9845053e+09 | N15: =$N$3*(1+$C$25)^12 -> 1.4594722e+08 | O15: =0.04*L15 -> 1.5938021e+08 | P15: 0 | Q15: =O15-N15 -> 13432995 | R15: =(R14+Q15)*1.16 -> 1.1179904e+09 | S15: 12
C16: 2039 | D16: =L15-(O15+P15) -> 3.8251251e+09 | E16: 0.070406 | F16: =F5 -> 0.1111488 | G16: =D16*0.6 -> 2.2950751e+09 | H16: =D16*0.4 -> 1.53005e+09 | I16: =G16*(1+E16) -> 2.4566621e+09 | J16: =H16*F16 -> 1.7006323e+08 | K16: =G16*'[1]Доходность акций'!$H$14*0.87 -> 1.7863014e+08 | L16: =SUM(H16:K16) -> 4.3354055e+09 | N16: =$N$3*(1+$C$25)^13 -> 1.6011869e+08 | O16: =0.04*L16 -> 1.7341622e+08 | P16: 0 | Q16: =O16-N16 -> 13297529 | R16: =(R15+Q16)*1.16 -> 1.312294e+09 | S16: 13
C17: 2040 | D17: =L16-(O16+P16) -> 4.1619893e+09 | E17: 0.070406 | F17: =F5 -> 0.1111488 | G17: =D17*0.6 -> 2.4971936e+09 | H17: =D17*0.4 -> 1.6647957e+09 | I17: =G17*(1+E17) -> 2.673011e+09 | J17: =H17*F17 -> 1.8504005e+08 | K17: =G17*'[1]Доходность акций'!$H$14*0.87 -> 1.9436142e+08 | L17: =SUM(H17:K17) -> 4.7172082e+09 | N17: =$N$3*(1+$C$25)^14 -> 1.7566622e+08 | O17: =0.04*L17 -> 1.8868833e+08 | P17: 0 | Q17: =O17-N17 -> 13022111 | R17: =(R16+Q17)*1.16 -> 1.5373667e+09 | S17: 14
C18: 2041 | D18: =L17-(O17+P17) -> 4.5285199e+09 | E18: 0.340468 | F18: =F5 -> 0.1111488 | G18: =D18*0.6 -> 2.7171119e+09 | H18: =D18*0.4 -> 1.8114079e+09 | I18: =G18*(1+E18) -> 3.6422016e+09 | J18: =H18*F18 -> 2.0133582e+08 | K18: =G18*'[1]Доходность акций'!$H$14*0.87 -> 2.1147809e+08 | L18: =SUM(H18:K18) -> 5.8664234e+09 | N18: =$N$3*(1+$C$25)^15 -> 1.9272341e+08 | O18: =0.04*L18 -> 2.3465694e+08 | P18: 0 | Q18: =O18-N18 -> 41933531 | R18: =(R17+Q18)*1.16 -> 1.8319883e+09 | S18: 15
C19: 2042 | D19: =L18-(O18+P18) -> 5.6317665e+09 | E19: 0.479212 | F19: =F5 -> 0.1111488 | G19: =D19*0.6 -> 3.3790599e+09 | H19: =D19*0.4 -> 2.2527066e+09 | I19: =G19*(1+E19) -> 4.9983459e+09 | J19: =H19*F19 -> 2.5038563e+08 | K19: =G19*'[1]Доходность акций'!$H$14*0.87 -> 2.6299879e+08 | L19: =SUM(H19:K19) -> 7.764437e+09 | N19: =$N$3*(1+$C$25)^16 -> 2.1143685e+08 | O19: =0.04*L19 -> 3.1057748e+08 | P19: 0 | Q19: =O19-N19 -> 99140629 | R19: =(R18+Q19)*1.16 -> 2.2401095e+09 | S19: 16
C20: 2043 | D20: =L19-(O19+P19) -> 7.4538595e+09 | E20: -0.043334 | F20: =F5 -> 0.1111488 | G20: =D20*0.6 -> 4.4723157e+09 | H20: =D20*0.4 -> 2.9815438e+09 | I20: =G20*(1+E20) -> 4.2785124e+09 | J20: =H20*F20 -> 3.3139501e+08 | K20: =G20*'[1]Доходность акций'!$H$14*0.87 -> 3.4808901e+08 | L20: =SUM(H20:K20) -> 7.9395402e+09 | N20: =$N$3*(1+$C$25)^17 -> 2.3196737e+08 | O20: =0.04*L20 -> 3.1758161e+08 | P20: 0 | Q20: =O20-N20 -> 85614240 | R20: =(R19+Q20)*1.16 -> 2.6978396e+09 | S20: 17
C21: 2044 | D21: =L20-(O20+P20) -> 7.6219586e+09 | E21: 0.158484 | F21: =F5 -> 0.1111488 | G21: =D21*0.6 -> 4.5731751e+09 | H21: =D21*0.4 -> 3.0487834e+09 | I21: =G21*(1+E21) -> 5.2979502e+09 | J21: =H21*F21 -> 3.3886862e+08 | K21: =G21*'[1]Доходность акций'!$H$14*0.87 -> 3.5593909e+08 | L21: =SUM(H21:K21) -> 9.0415414e+09 | N21: =$N$3*(1+$C$25)^18 -> 2.544914e+08 | O21: =0.04*L21 -> 3.6166165e+08 | P21: 0 | Q21: =O21-N21 -> 1.0717026e+08 | R21: =(R20+Q21)*1.16 -> 3.2538114e+09 | S21: 18
C22: 2045 | D22: =L21-(O21+P21) -> 8.6798797e+09 | E22: 0.340468 | F22: =F5 -> 0.1111488 | G22: =D22*0.6 -> 5.2079278e+09 | H22: =D22*0.4 -> 3.4719519e+09 | I22: =G22*(1+E22) -> 6.9810606e+09 | J22: =H22*F22 -> 3.8590329e+08 | K22: =G22*'[1]Доходность акций'!$H$14*0.87 -> 4.0534313e+08 | L22: =SUM(H22:K22) -> 1.1244259e+10 | N22: =$N$3*(1+$C$25)^19 -> 2.7920251e+08 | O22: =0.04*L22 -> 4.4977036e+08 | P22: 0 | Q22: =O22-N22 -> 1.7056784e+08 | R22: =(R21+Q22)*1.16 -> 3.9722799e+09 | S22: 19
C23: 2046 | D23: =L22-(O22+P22) -> 1.0794489e+10 | E23: 0.158484 | F23: =F5 -> 0.1111488 | G23: =D23*0.6 -> 6.4766931e+09 | H23: =D23*0.4 -> 4.3177954e+09 | I23: =G23*(1+E23) -> 7.5031454e+09 | J23: =H23*F23 -> 4.7991778e+08 | K23: =G23*'[1]Доходность акций'!$H$14*0.87 -> 5.0409359e+08 | L23: =SUM(I23,K23) -> 8.0072389e+09 | N23: =$N$3*(1+$C$25)^20 -> 3.0631308e+08 | O23: =0.04*L23 -> 3.2028956e+08 | P23: 0 | Q23: =O23-N23 -> 13976480 | R23: =(R22+Q23)*1.16 -> 4.6240574e+09 | S23: 20
B25: Инфляция | C25: 0.0971
B26: НДФЛ | C26: 0.13

Sheet Сценарий кризиса
D2: Брокерский счет | E2: Доходость акций | F2: Доходость облигаций | G2: Сумма направляемая на акции, руб | H2: Сумма направляемая на облигации, руб | I2: Рост акций, руб | J2: Купонный доход, руб | K2: Дивидендный доход, руб | L2: Стоимость портфеля на конец года, руб | M2: Резерв, руб | N2: Расходы, руб | O2: Вывод 4% | P2: Доп вывод | Q2: Кладёт на накоп счёт | R2: Накоп счет на конец года
C3: 2026 | D3: 656600000 | E3: 0.06741 | F3: 0.137934 | G3: =D3*0.6 -> 393960000 | H3: =D3*0.4 -> 262640000 | I3: =G3*(1+E3) -> 4.2051684e+08 | J3: =H3*F3 -> 36226986 | K3: =G3*'[1]Доходность акций'!$H$14*0.87 -> 30662671 | L3: =SUM(H3:K3) -> 7.500465e+08 | M3: 281400000 | N3: 48000000 | O3: =0.04*L3 -> 30001860 | Q3: =O3-P3 -> 30001860 | R3: =Q3*1.16 -> 34802158
C4: 2027 | D4: =L3-(O3+P3) -> 7.2004464e+08 | E4: 0.326 | F4: 0.097434 | G4: =D4*0.6 -> 4.3202678e+08 | H4: =D4*0.4 -> 2.8801786e+08 | I4: =G4*(1+E4) -> 5.7286752e+08 | J4: =H4*F4 -> 28062732 | K4: =G4*'[1]Доходность акций'!$H$14*0.87 -> 33625483 | L4: =SUM(H4:K4) -> 9.2257359e+08 | M4: =M3-N3 -> 233400000 | N4: =$N$3*(1+$C$25)^1 -> 53140800 | O4: =0.04*L4 -> 36902943 | Q4: =O4-P4 -> 36902943 | R4: =(R3+Q4)*1.16 -> 83177917 | S4: 1
C5: 2028 | D5: =L4-(O4+P4) -> 8.8567064e+08 | E5: 0.15174 | F5: 0.104184 | G5: =D5*0.6 -> 5.3140239e+08 | H5: =D5*0.4 -> 3.5426826e+08 | I5: =G5*(1+E5) -> 6.1203738e+08 | J5: =H5*F5 -> 36909084 | K5: =G5*'[1]Доходность акций'!$H$14*0.87 -> 41360079 | L5: =SUM(H5:K5) -> 1.0445748e+09 | M5: =M4-N4 -> 180259200 | N5: =$N$3*(1+$C$25)^2 -> 58832180 | O5: =0.04*L5 -> 41782992 | Q5: =O5-P5 -> 41782992 | R5: =(R4+Q5)*1.16 -> 1.4495465e+08 | S5: 2
C6: 2029 | D6: =L5-(O5+P5) -> 1.0027918e+09 | E6: 0.15174 | F6: =F5 -> 0.104184 | G6: =D6*0.6 -> 6.0167509e+08 | H6: =D6*0.4 -> 4.0111672e+08 | I6: =G6*(1+E6) -> 6.9297326e+08 | J6: =H6*F6 -> 41789945 | K6: =G6*'[1]Доходность акций'!$H$14*0.87 -> 46829539 | L6: =SUM(H6:K6) -> 1.1827095e+09 | M6: =M5-N5 -> 1.2142702e+08 | N6: =$N$3*(1+$C$25)^3 -> 65133106 | O6: =0.04*L6 -> 47308379 | Q6: =O6-P6 -> 47308379 | R6: =(R5+Q6)*1.16 -> 2.2302512e+08 | S6: 3
C7: 2030 | D7: =L6-(O6+P6) -> 1.1354011e+09 | E7: -0.04149 | F7: =F5 -> 0.104184 | G7: =D7*0.6 -> 6.8124066e+08 | H7: =D7*0.4 -> 4.5416044e+08 | I7: =G7*(1+E7) -> 6.5297598e+08 | J7: =H7*F7 -> 47316251 | K7: =G7*'[1]Доходность акций'!$H$14*0.87 -> 53022282 | L7: =SUM(H7:K7) -> 1.207475e+09 | M7: =M6-N6 -> 56293914 | N7: =$N$3*(1+$C$25)^4 -> 72108862 | O7: =0.04*L7 -> 48298998 | Q7: =O7-(N7-M7) -> 32484051 | R7: =(R6+Q7)*1.16 -> 2.9639064e+08 | S7: 4
C8: 2031 | D8: =L7-(O7+P7) -> 1.159176e+09 | E8: 0.45882 | F8: =F5 -> 0.104184 | G8: =D8*0.6 -> 6.9550557e+08 | H8: =D8*0.4 -> 4.6367038e+08 | I8: =G8*(1+E8) -> 1.0146174e+09 | J8: =H8*F8 -> 48307035 | K8: =G8*'[1]Доходность акций'!$H$14*0.87 -> 54132548 | L8: =SUM(H8:K8) -> 1.5807274e+09 | M8: 0 | N8: =$N$3*(1+$C$25)^5 -> 79831721 | O8: =0.04*L8 -> 63229096 | P8: =N8-O8 -> 16602625 | Q8: 0 | R8: =(R7+Q8)*1.16 -> 3.4381314e+08 | S8: 5
C9: 2032 | D9: =L8-(O8+P8) -> 1.5008957e+09 | E9: 0.06741 | F9: =F5 -> 0.104184 | G9: =D9*0.6 -> 9.0053741e+08 | H9: =D9*0.4 -> 6.0035827e+08 | I9: =G9*(1+E9) -> 9.6124264e+08 | J9: =H9*F9 -> 62547726 | K9: =G9*'[1]Доходность акций'!$H$14*0.87 -> 70090574 | L9: =SUM(H9:K9) -> 1.6942392e+09 | N9: =$N$3*(1+$C$25)^6 -> 88381698 | O9: =0.04*L9 -> 67769568 | P9: =N9-O9 -> 20612130 | Q9: 0 | R9: =(R8+Q9)*1.16 -> 3.9882324e+08 | S9: 6
C10: 2033 | D10: =L9-(O9+P9) -> 1.6058575e+09 | E10: 0.14742 | F10: =F5 -> 0.104184 | G10: =D10*0.6 -> 9.6351451e+08 | H10: =D10*0.4 -> 6.42343e+08 | I10: =G10*(1+E10) -> 1.1055558e+09 | J10: =H10*F10 -> 66921864 | K10: =G10*'[1]Доходность акций'!$H$14*0.87 -> 74992203 | L10: =SUM(H10:K10) -> 1.8898129e+09 | N10: =$N$3*(1+$C$25)^7 -> 97847378 | O10: =0.04*L10 -> 75592516 | P10: =N10-O10 -> 22254863 | Q10: 0 | R10: =(R9+Q10)*1.16 -> 4.6263496e+08 | S10: 7
C11: 2034 | D11: =L10-(O10+P10) -> 1.7919655e+09 | E11: 0.45882 | F11: =F5 -> 0.104184 | G11: =D11*0.6 -> 1.0751793e+09 | H11: =D11*0.4 -> 7.167862e+08 | I11: =G11*(1+E11) -> 1.5684931e+09 | J11: =H11*F11 -> 74677654 | K11: =G11*'[1]Доходность акций'!$H$14*0.87 -> 83683291 | L11: =SUM(H11:K11) -> 2.4436402e+09 | N11: =$N$3*(1+$C$25)^8 -> 1.0832683e+08 | O11: =0.04*L11 -> 97745609 | P11: =N11-O11 -> 10581223 | Q11: 0 | R11: =(R10+Q11)*1.16 -> 5.3665655e+08 | S11: 8
C12: 2035 | D12: =L11-(O11+P11) -> 2.3353134e+09 | E12: 0.326 | F12: =F5 -> 0.104184 | G12: =D12*0.6 -> 1.401188e+09 | H12: =D12*0.4 -> 9.3412536e+08 | I12: =G12*(1+E12) -> 1.8579753e+09 | J12: =H12*F12 -> 97320916 | K12: =G12*'[1]Доходность акций'!$H$14*0.87 -> 1.0905718e+08 | L12: =SUM(H12:K12) -> 2.9984788e+09 | N12: =$N$3*(1+$C$25)^9 -> 1.1992864e+08 | O12: =0.04*L12 -> 1.1993915e+08 | P12: 0 | Q12: =O12-N12 -> 10515.64 | R12: =(R11+Q12)*1.16 -> 6.225338e+08 | S12: 9
C13: 2036 | D13: =L12-(O12+P12) -> 2.8785396e+09 | E13: -0.04149 | F13: =F5 -> 0.104184 | G13: =D13*0.6 -> 1.7271238e+09 | H13: =D13*0.4 -> 1.1514159e+09 | I13: =G13*(1+E13) -> 1.6554654e+09 | J13: =H13*F13 -> 1.1995911e+08 | K13: =G13*'[1]Доходность акций'!$H$14*0.87 -> 1.3442539e+08 | L13: =SUM(H13:K13) -> 3.0612658e+09 | N13: =$N$3*(1+$C$25)^10 -> 1.3277299e+08 | O13: =0.04*L13 -> 1.2245063e+08 | P13: =N13-O13 -> 10322362 | Q13: 0 | R13: =(R12+Q13)*1.16 -> 7.2213921e+08 | S13: 10
C14: 2037 | D14: =L13-(O13+P13) -> 2.9284928e+09 | E14: 0.06741 | F14: =F5 -> 0.104184 | G14: =D14*0.6 -> 1.7570957e+09 | H14: =D14*0.4 -> 1.1713971e+09 | I14: =G14*(1+E14) -> 1.8755415e+09 | J14: =H14*F14 -> 1.2204084e+08 | K14: =G14*'[1]Доходность акций'!$H$14*0.87 -> 1.3675816e+08 | L14: =SUM(H14:K14) -> 3.3057376e+09 | N14: =$N$3*(1+$C$25)^11 -> 1.4699298e+08 | O14: =0.04*L14 -> 1.322295e+08 | P14: =N14-O14 -> 14763476 | Q14: 0 | R14: =(R13+Q14)*1.16 -> 8.3768148e+08 | S14: 11
C15: 2038 | D15: =L14-(O14+P14) -> 3.1587446e+09 | E15: 0.06741 | F15: =F5 -> 0.104184 | G15: =D15*0.6 -> 1.8952468e+09 | H15: =D15*0.4 -> 1.2634979e+09 | I15: =G15*(1+E15) -> 2.0230054e+09 | J15: =H15*F15 -> 1.3163626e+08 | K15: =G15*'[1]Доходность акций'!$H$14*0.87 -> 1.4751073e+08 | L15: =SUM(H15:K15) -> 3.5656502e+09 | N15: =$N$3*(1+$C$25)^12 -> 1.6273593e+08 | O15: =0.04*L15 -> 1.4262601e+08 | P15: =N15-O15 -> 20109921 | Q15: 0 | R15: =(R14+Q15)*1.16 -> 9.7171052e+08 | S15: 12
C16: 2039 | D16: =L15-(O15+P15) -> 3.4029143e+09 | E16: 0.06741 | F16: =F5 -> 0.104184 | G16: =D16*0.6 -> 2.0417486e+09 | H16: =D16*0.4 -> 1.3611657e+09 | I16: =G16*(1+E16) -> 2.1793828e+09 | J16: =H16*F16 -> 1.4181169e+08 | K16: =G16*'[1]Доходность акций'!$H$14*0.87 -> 1.5891325e+08 | L16: =SUM(H16:K16) -> 3.8412735e+09 | N16: =$N$3*(1+$C$25)^13 -> 1.8016495e+08 | O16: =0.04*L16 -> 1.5365094e+08 | P16: =N16-O16 -> 26514007 | Q16: 0 | R16: =(R15+Q16)*1.16 -> 1.1271842e+09 | S16: 13
C17: 2040 | D17: =L16-(O16+P16) -> 3.6611085e+09 | E17: 0.06741 | F17: =F5 -> 0.104184 | G17: =D17*0.6 -> 2.1966651e+09 | H17: =D17*0.4 -> 1.4644434e+09 | I17: =G17*(1+E17) -> 2.3447423e+09 | J17: =H17*F17 -> 1.5257157e+08 | K17: =G17*'[1]Доходность акций'!$H$14*0.87 -> 1.7097071e+08 | L17: =SUM(H17:K17) -> 4.132728e+09 | N17: =$N$3*(1+$C$25)^14 -> 1.9946061e+08 | O17: =0.04*L17 -> 1.6530912e+08 | P17: =N17-O17 -> 34151492 | Q17: 0 | R17: =(R16+Q17)*1.16 -> 1.3075337e+09 | S17: 14
C18: 2041 | D18: =L17-(O17+P17) -> 3.9332674e+09 | E18: 0.326 | F18: =F5 -> 0.104184 | G18: =D18*0.6 -> 2.3599604e+09 | H18: =D18*0.4 -> 1.573307e+09 | I18: =G18*(1+E18) -> 3.1293075e+09 | J18: =H18*F18 -> 1.6391341e+08 | K18: =G18*'[1]Доходность акций'!$H$14*0.87 -> 1.836803e+08 | L18: =SUM(H18:K18) -> 5.0502082e+09 | N18: =$N$3*(1+$C$25)^15 -> 2.2082284e+08 | O18: =0.04*L18 -> 2.0200833e+08 | P18: =N18-O18 -> 18814515 | Q18: 0 | R18: =(R17+Q18)*1.16 -> 1.5167391e+09 | S18: 15
C19: 2042 | D19: =L18-(O18+P18) -> 4.8293854e+09 | E19: 0.45882 | F19: =F5 -> 0.104184 | G19: =D19*0.6 -> 2.8976312e+09 | H19: =D19*0.4 -> 1.9317542e+09 | I19: =G19*(1+E19) -> 4.2271224e+09 | J19: =H19*F19 -> 2.0125787e+08 | K19: =G19*'[1]Доходность акций'!$H$14*0.87 -> 2.2552826e+08 | L19: =SUM(H19:K19) -> 6.5856627e+09 | N19: =$N$3*(1+$C$25)^16 -> 2.4447297e+08 | O19: =0.04*L19 -> 2.6342651e+08 | P19: 0 | Q19: =O19-N19 -> 18953536 | R19: =(R18+Q19)*1.16 -> 1.7814034e+09 | S19: 16
C20: 2043 | D20: =L19-(O19+P19) -> 6.3222362e+09 | E20: -0.04149 | F20: =F5 -> 0.104184 | G20: =D20*0.6 -> 3.7933417e+09 | H20: =D20*0.4 -> 2.5288945e+09 | I20: =G20*(1+E20) -> 3.635956e+09 | J20: =H20*F20 -> 2.6347034e+08 | K20: =G20*'[1]Доходность акций'!$H$14*0.87 -> 2.9524314e+08 | L20: =SUM(H20:K20) -> 6.7235639e+09 | N20: =$N$3*(1+$C$25)^17 -> 2.7065603e+08 | O20: =0.04*L20 -> 2.6894256e+08 | P20: =N20-O20 -> 1713469.7 | Q20: 0 | R20: =(R19+Q20)*1.16 -> 2.066428e+09 | S20: 17
C21: 2044 | D21: =L20-(O20+P20) -> 6.4529079e+09 | E21: 0.15174 | F21: =F5 -> 0.104184 | G21: =D21*0.6 -> 3.8717447e+09 | H21: =D21*0.4 -> 2.5811631e+09 | I21: =G21*(1+E21) -> 4.4592433e+09 | J21: =H21*F21 -> 2.689159e+08 | K21: =G21*'[1]Доходность акций'!$H$14*0.87 -> 3.013454e+08 | L21: =SUM(H21:K21) -> 7.6106677e+09 | N21: =$N$3*(1+$C$25)^18 -> 2.9964329e+08 | O21: =0.04*L21 -> 3.0442671e+08 | P21: 0 | Q21: =O21-N21 -> 4783422.8 | R21: =(R20+Q21)*1.16 -> 2.4026052e+09 | S21: 18
C22: 2045 | D22: =L21-(O21+P21) -> 7.306241e+09 | E22: 0.326 | F22: =F5 -> 0.104184 | G22: =D22*0.6 -> 4.3837446e+09 | H22: =D22*0.4 -> 2.9224964e+09 | I22: =G22*(1+E22) -> 5.8128454e+09 | J22: =H22*F22 -> 3.0447737e+08 | K22: =G22*'[1]Доходность акций'!$H$14*0.87 -> 3.4119535e+08 | L22: =SUM(H22:K22) -> 9.3810145e+09 | N22: =$N$3*(1+$C$25)^19 -> 3.3173508e+08 | O22: =0.04*L22 -> 3.7524058e+08 | P22: 0 | Q22: =O22-N22 -> 43505497 | R22: =(R21+Q22)*1.16 -> 2.8374884e+09 | S22: 19
C23: 2046 | D23: =L22-(O22+P22) -> 9.0057739e+09 | E23: 0.15174 | F23: =F5 -> 0.104184 | G23: =D23*0.6 -> 5.4034643e+09 | H23: =D23*0.4 -> 3.6023096e+09 | I23: =G23*(1+E23) -> 6.223386e+09 | J23: =H23*F23 -> 3.7530302e+08 | K23: =G23*'[1]Доходность акций'!$H$14*0.87 -> 4.2056211e+08 | L23: =SUM(I23,K23) -> 6.6439481e+09 | N23: =$N$3*(1+$C$25)^20 -> 3.6726391e+08 | O23: =0.04*L23 -> 2.6575792e+08 | P23: =N23-O23 -> 1.0150598e+08 | Q23: 0 | R23: =(R22+Q23)*1.16 -> 3.2914866e+09 | S23: 20
B25: Инфляция | C25: 0.1071
B26: НДФЛ | C26: 0.13
B30: Если сократить расходы:
D32: Брокерский счет | E32: Доходость акций | F32: Доходость облигаций | G32: Сумма направляемая на акции, руб | H32: Сумма направляемая на облигации, руб | I32: Рост акций, руб | J32: Купонный доход, руб | K32: Дивидендный доход, руб | L32: Стоимость портфеля на конец года, руб | M32: Резерв, руб | N32: Расходы, руб | O32: Вывод 4% | P32: Доп вывод | Q32: Кладёт на накоп счёт | R32: Накоп счет на конец года
C33: 2026 | D33: 656600000 | E33: 0.06741 | F33: 0.137934 | G33: =D33*0.6 -> 393960000 | H33: =D33*0.4 -> 262640000 | I33: =G33*(1+E33) -> 4.2051684e+08 | J33: =H33*F33 -> 36226986 | K33: =G33*'[1]Доходность акций'!$H$14*0.87 -> 30662671 | L33: =SUM(H33:K33) -> 7.500465e+08 | M33: 281400000 | N33: 36000000 | O33: =0.04*L33 -> 30001860 | Q33: =O33-P33 -> 30001860 | R33: =Q33*1.16 -> 34802158
C34: 2027 | D34: =L33-(O33+P33) -> 7.2004464e+08 | E34: 0.326 | F34: 0.097434 | G34: =D34*0.6 -> 4.3202678e+08 | H34: =D34*0.4 -> 2.8801786e+08 | I34: =G34*(1+E34) -> 5.7286752e+08 | J34: =H34*F34 -> 28062732 | K34: =G34*'[1]Доходность акций'!$H$14*0.87 -> 33625483 | L34: =SUM(H34:K34) -> 9.2257359e+08 | M34: =M33-N33 -> 245400000 | N34: =$N$3*(1+$C$25)^1 -> 53140800 | O34: =0.04*L34 -> 36902943 | Q34: =O34-P34 -> 36902943 | R34: =(R33+Q34)*1.16 -> 83177917 | S34: 1
C35: 2028 | D35: =L34-(O34+P34) -> 8.8567064e+08 | E35: 0.15174 | F35: 0.104184 | G35: =D35*0.6 -> 5.3140239e+08 | H35: =D35*0.4 -> 3.5426826e+08 | I35: =G35*(1+E35) -> 6.1203738e+08 | J35: =H35*F35 -> 36909084 | K35: =G35*'[1]Доходность акций'!$H$14*0.87 -> 41360079 | L35: =SUM(H35:K35) -> 1.0445748e+09 | M35: =M34-N34 -> 192259200 | N35: =$N$3*(1+$C$25)^2 -> 58832180 | O35: =0.04*L35 -> 41782992 | Q35: =O35-P35 -> 41782992 | R35: =(R34+Q35)*1.16 -> 1.4495465e+08 | S35: 2
C36: 2029 | D36: =L35-(O35+P35) -> 1.0027918e+09 | E36: 0.15174 | F36: =F35 -> 0.104184 | G36: =D36*0.6 -> 6.0167509e+08 | H36: =D36*0.4 -> 4.0111672e+08 | I36: =G36*(1+E36) -> 6.9297326e+08 | J36: =H36*F36 -> 41789945 | K36: =G36*'[1]Доходность акций'!$H$14*0.87 -> 46829539 | L36: =SUM(H36:K36) -> 1.1827095e+09 | M36: =M35-N35 -> 1.3342702e+08 | N36: =$N$3*(1+$C$25)^3 -> 65133106 | O36: =0.04*L36 -> 47308379 | Q36: =O36-P36 -> 47308379 | R36: =(R35+Q36)*1.16 -> 2.2302512e+08 | S36: 3
C37: 2030 | D37: =L36-(O36+P36) -> 1.1354011e+09 | E37: -0.04149 | F37: =F35 -> 0.104184 | G37: =D37*0.6 -> 6.8124066e+08 | H37: =D37*0.4 -> 4.5416044e+08 | I37: =G37*(1+E37) -> 6.5297598e+08 | J37: =H37*F37 -> 47316251 | K37: =G37*'[1]Доходность акций'!$H$14*0.87 -> 53022282 | L37: =SUM(H37:K37) -> 1.207475e+09 | M37: =M36-N36 -> 68293914 | N37: =$N$3*(1+$C$25)^4 -> 72108862 | O37: =0.04*L37 -> 48298998 | Q37: =O37-P37 -> 48298998 | R37: =(R36+Q37)*1.16 -> 3.1473598e+08 | S37: 4
C38: 2031 | D38: =L37-(O37+P37) -> 1.159176e+09 | E38: 0.45882 | F38: =F35 -> 0.104184 | G38: =D38*0.6 -> 6.9550557e+08 | H38: =D38*0.4 -> 4.6367038e+08 | I38: =G38*(1+E38) -> 1.0146174e+09 | J38: =H38*F38 -> 48307035 | K38: =G38*'[1]Доходность акций'!$H$14*0.87 -> 54132548 | L38: =SUM(H38:K38) -> 1.5807274e+09 | M38: =0 -> 0 | N38: =$N$3*(1+$C$25)^5 -> 79831721 | O38: =0.04*L38 -> 63229096 | P38: =N38-O38 -> 16602625 | Q38: =O38-P38 -> 46626471 | R38: =(R37+Q38)*1.16 -> 4.1918044e+08 | S38: 5
C39: 2032 | D39: =L38-(O38+P38) -> 1.5008957e+09 | E39: 0.06741 | F39: =F35 -> 0.104184 | G39: =D39*0.6 -> 9.0053741e+08 | H39: =D39*0.4 -> 6.0035827e+08 | I39: =G39*(1+E39) -> 9.6124264e+08 | J39: =H39*F39 -> 62547726 | K39: =G39*'[1]Доходность акций'!$H$14*0.87 -> 70090574 | L39: =SUM(H39:K39) -> 1.6942392e+09 | M39: 0 | N39: =$N$3*(1+$C$25)^6 -> 88381698 | O39: =0.04*L39 -> 67769568 | P39: =N39-O39 -> 20612130 | Q39: =O39-P39 -> 47157439 | R39: =(R38+Q39)*1.16 -> 5.4095194e+08 | S39: 6
C40: 2033 | D40: =L39-(O39+P39) -> 1.6058575e+09 | E40: 0.14742 | F40: =F35 -> 0.104184 | G40: =D40*0.6 -> 9.6351451e+08 | H40: =D40*0.4 -> 6.42343e+08 | I40: =G40*(1+E40) -> 1.1055558e+09 | J40: =H40*F40 -> 66921864 | K40: =G40*'[1]Доходность акций'!$H$14*0.87 -> 74992203 | L40: =SUM(H40:K40) -> 1.8898129e+09 | N40: =$N$3*(1+$C$25)^7 -> 97847378 | O40: =0.04*L40 -> 75592516 | P40: =N40-O40 -> 22254863 | Q40: =O40-P40 -> 53337653 | R40: =(R39+Q40)*1.16 -> 6.8937593e+08 | S40: 7
C41: 2034 | D41: =L40-(O40+P40) -> 1.7919655e+09 | E41: 0.45882 | F41: =F35 -> 0.104184 | G41: =D41*0.6 -> 1.0751793e+09 | H41: =D41*0.4 -> 7.167862e+08 | I41: =G41*(1+E41) -> 1.5684931e+09 | J41: =H41*F41 -> 74677654 | K41: =G41*'[1]Доходность акций'!$H$14*0.87 -> 83683291 | L41: =SUM(H41:K41) -> 2.4436402e+09 | N41: =$N$3*(1+$C$25)^8 -> 1.0832683e+08 | O41: =0.04*L41 -> 97745609 | P41: =N41-O41 -> 10581223 | Q41: =O41-P41 -> 87164386 | R41: =(R40+Q41)*1.16 -> 9.0078676e+08 | S41: 8
C42: 2035 | D42: =L41-(O41+P41) -> 2.3353134e+09 | E42: 0.326 | F42: =F35 -> 0.104184 | G42: =D42*0.6 -> 1.401188e+09 | H42: =D42*0.4 -> 9.3412536e+08 | I42: =G42*(1+E42) -> 1.8579753e+09 | J42: =H42*F42 -> 97320916 | K42: =G42*'[1]Доходность акций'!$H$14*0.87 -> 1.0905718e+08 | L42: =SUM(H42:K42) -> 2.9984788e+09 | N42: =$N$3*(1+$C$25)^9 -> 1.1992864e+08 | O42: =0.04*L42 -> 1.1993915e+08 | P42: 0 | Q42: =O42-P42 -> 1.1993915e+08 | R42: =(R41+Q42)*1.16 -> 1.1840421e+09 | S42: 9
C43: 2036 | D43: =L42-(O42+P42) -> 2.8785396e+09 | E43: -0.04149 | F43: =F35 -> 0.104184 | G43: =D43*0.6 -> 1.7271238e+09 | H43: =D43*0.4 -> 1.1514159e+09 | I43: =G43*(1+E43) -> 1.6554654e+09 | J43: =H43*F43 -> 1.1995911e+08 | K43: =G43*'[1]Доходность акций'!$H$14*0.87 -> 1.3442539e+08 | L43: =SUM(H43:K43) -> 3.0612658e+09 | N43: =$N$3*(1+$C$25)^10 -> 1.3277299e+08 | O43: =0.04*L43 -> 1.2245063e+08 | P43: =N43-O43 -> 10322362 | Q43: =O43-P43 -> 1.1212827e+08 | R43: =(R42+Q43)*1.16 -> 1.5035576e+09 | S43: 10
C44: 2037 | D44: =L43-(O43+P43) -> 2.9284928e+09 | E44: 0.06741 | F44: =F35 -> 0.104184 | G44: =D44*0.6 -> 1.7570957e+09 | H44: =D44*0.4 -> 1.1713971e+09 | I44: =G44*(1+E44) -> 1.8755415e+09 | J44: =H44*F44 -> 1.2204084e+08 | K44: =G44*'[1]Доходность акций'!$H$14*0.87 -> 1.3675816e+08 | L44: =SUM(H44:K44) -> 3.3057376e+09 | N44: =$N$3*(1+$C$25)^11 -> 1.4699298e+08 | O44: =0.04*L44 -> 1.322295e+08 | P44: =N44-O44 -> 14763476 | Q44: =O44-P44 -> 1.1746603e+08 | R44: =(R43+Q44)*1.16 -> 1.8803874e+09 | S44: 11
C45: 2038 | D45: =L44-(O44+P44) -> 3.1587446e+09 | E45: 0.06741 | F45: =F35 -> 0.104184 | G45: =D45*0.6 -> 1.8952468e+09 | H45: =D45*0.4 -> 1.2634979e+09 | I45: =G45*(1+E45) -> 2.0230054e+09 | J45: =H45*F45 -> 1.3163626e+08 | K45: =G45*'[1]Доходность акций'!$H$14*0.87 -> 1.4751073e+08 | L45: =SUM(H45:K45) -> 3.5656502e+09 | N45: =$N$3*(1+$C$25)^12 -> 1.6273593e+08 | O45: =0.04*L45 -> 1.4262601e+08 | P45: =N45-O45 -> 20109921 | Q45: =O45-P45 -> 1.2251609e+08 | R45: =(R44+Q45)*1.16 -> 2.323368e+09 | S45: 12
C46: 2039 | D46: =L45-(O45+P45) -> 3.4029143e+09 | E46: 0.06741 | F46: =F35 -> 0.104184 | G46: =D46*0.6 -> 2.0417486e+09 | H46: =D46*0.4 -> 1.3611657e+09 | I46: =G46*(1+E46) -> 2.1793828e+09 | J46: =H46*F46 -> 1.4181169e+08 | K46: =G46*'[1]Доходность акций'!$H$14*0.87 -> 1.5891325e+08 | L46: =SUM(H46:K46) -> 3.8412735e+09 | N46: =$N$3*(1+$C$25)^13 -> 1.8016495e+08 | O46: =0.04*L46 -> 1.5365094e+08 | P46: =N46-O46 -> 26514007 | Q46: =O46-P46 -> 1.2713693e+08 | R46: =(R45+Q46)*1.16 -> 2.8425858e+09 | S46: 13
...
